Workbook
Name _41366429BCF84A0DAB085C4B6EE4E5D6: Sheet4!$A$1:$A$4
Name _AA1D6546EDDE479FB576CF0D15165BC5: OFFSET(Sheet2!$A$1,0,0,COUNTA(Sheet2!$A$1:$A$70)-COUNTIF(Sheet2!$A$1:$A$70,""),1)
Name _Air_source: Sheet2!$D$1:$E$1
Name _Ammeter: Sheet2!$D$2:$E$2
Name _B2C6BD42989A456297BA9F2F2B621051: Sheet3!$A$1:$A$7
Name _Barcode_scanner: Sheet2!$D$3:$E$3
Name _Burner: Sheet2!$D$4:$F$4
Name _CCD: Sheet2!$D$5:$H$5
Name _Communication__internal_equipment_: Sheet2!$D$6:$E$6
Name _Constant_temperature_system: Sheet2!$D$7:$F$7
Name _Counter: Sheet2!$D$8:$D$8
Name _Cylinder: Sheet2!$D$9:$F$9
Name _DD_motor: Sheet2!$D$10:$E$10
Name _Dot_Spray_glue_system: Sheet2!$D$11:$F$11
Name _Dynamic_balancing: Sheet2!$D$12:$E$12
Name _Electric_cylinder: Sheet2!$D$13:$F$13
Name _Electric_gripper: Sheet2!$D$14:$F$14
Name _Electric_spindle: Sheet2!$D$15:$E$15
Name _Electrostatic_eliminator: Sheet2!$D$16:$E$16
Name _EMG_stop_button: Sheet2!$D$17:$E$17
Name _Glue_dispensing_system: Sheet2!$D$18:$E$18
Name _Glue_supply_system: Sheet2!$D$19:$E$19
Name _High_frequency_equipment: Sheet2!$D$20:$G$20
Name _Horizontal_articulated_robot: Sheet2!$D$21:$G$21
Name _Induction_motor: Sheet2!$D$22:$E$22
Name _label_feeder: Sheet2!$D$23:$E$23
Name _Laser: Sheet2!$D$24:$E$24
Name _Life_control: Sheet2!$D$25:$E$25
Name _Light: Sheet2!$D$26:$E$26
Name _Linear_motor: Sheet2!$D$27:$D$27
Name _Locking_system: Sheet2!$D$28:$H$28
Name _M2M: Sheet2!$D$29:$E$29
Name _M2S: Sheet2!$D$30:$H$30
Name _Magnetizer: Sheet2!$D$31:$E$31
Name _Others: Sheet2!$D$32:$H$32
Name _Plug_in_feeder: Sheet2!$D$33:$G$33
Name _Poor_material: Sheet2!$D$34:$E$34
Name _Poor_production_quality: Sheet2!$D$35:$G$35
Name _Power_meter: Sheet2!$D$36:$E$36
Name _Power_roller: Sheet2!$D$37:$E$37
Name _Pressure_gauge: Sheet2!$D$38:$E$38
Name _Printer: Sheet2!$D$39:$E$39
Name _Process: Sheet2!$D$40:$N$40
Name _Push_Button: Sheet2!$D$41:$E$41
Name _RFID: Sheet2!$D$42:$E$42
Name _Safety_relay: Sheet2!$D$43:$E$43
Name _Safty_grating: Sheet2!$D$44:$E$44
Name _Screw_feeding_system: Sheet2!$D$45:$F$45
Name _Self_Control: Sheet2!$D$46:$E$46
Name _Sensor: Sheet2!$D$47:$E$47
Name _Servo_motor: Sheet2!$D$48:$J$48
Name _Servo_Press: Sheet2!$D$49:$G$49
Name _Sfatey_door: Sheet2!$D$50:$E$50
Name _Smoke_Alarm: Sheet2!$D$51:$E$51
Name _Soldering_system: Sheet2!$D$52:$E$52
Name _Stepper_motor: Sheet2!$D$53:$H$53
Name _Tachometer: Sheet2!$D$54:$E$54
Name _Tension_meter: Sheet2!$D$55:$E$55
Name _Test_system: Sheet2!$D$56:$M$56
Name _Testing_instrument: Sheet2!$D$57:$F$57

Sheet Sheet1
A1: 設備錯誤碼_x000D_ Machine error code_x000D_ 001-999 | B1: 警報分類（中文）_x000D_ Alert category | C1: 錯誤内容（中文）_x000D_ Error content_x000D_ （By元件功能定義）_x000D_ (define by component function) | D1: 故障現象描述（中文）_x000D_ breakdown detail description(Chinese) | E1: 故障現象描述（英文）_x000D_ breakdown detail description(English) | F1: 報錯模組名稱_x000D_ Error module name | G1: 警報觸發對應IO_x000D_ associated IO trigger by alert | H1: 元件代碼_x000D_ Component code_x000D_ eg. Cy_AA\Ms_B1 | I1: 元件代碼縮寫_x000D_ Component Code abbrevaiation | J1: 錯誤内容（中文）_x000D_ Error content_x000D_ （By元件功能定義）_x000D_ (define by component function) | K1: 錯誤内容（英文）_x000D_ Error content_x000D_ （By元件功能定義）_x000D_ (define by component function) | L1: Reason類別_x000D_ Reason category | M1: 原因描述（中文）_x000D_ Reason description | N1: 原因描述（英文）_x000D_ Reason description | O1: 處理對策（中文）_x000D_ Treatment countermeasure | P1: 處理對策（英文）_x000D_ Treatment countermeasure | Q1: DFOC Processing level_x000D_ P3: 遠程處理_x000D_ M2S2H(remote)_x000D_ P4：現場處理_x000D_ | R1: V20260130001E
A2: M-Error | B2: S-Error Type | C2: S-Error Desc | D2: M-Error Desc | E2: M-Error DescEn | F2: Error Module | G2: IONumber | H2: ComponentCode | I2: Component Code abbrevaiation | J2: New S-Error Desc | K2: New S-Error DescEn | L2: Reason category | M2: Reason Desc | N2: Reason DescEn | O2: Solution Desc | P2: Solution Desc | Q2: DFOC Level
I3: =IFERROR(INDEX(Sheet2!$C1:$C70,MATCH($B3,Sheet2!$B1:$B70,0)),"")
I4: =IFERROR(INDEX(Sheet2!$C1:$C70,MATCH($B4,Sheet2!$B1:$B70,0)),"")
I5: =IFERROR(INDEX(Sheet2!$C1:$C70,MATCH($B5,Sheet2!$B1:$B70,0)),"")
I6: =IFERROR(INDEX(Sheet2!$C1:$C70,MATCH($B6,Sheet2!$B1:$B70,0)),"")
I7: =IFERROR(INDEX(Sheet2!$C1:$C70,MATCH($B7,Sheet2!$B1:$B70,0)),"")
I8: =IFERROR(INDEX(Sheet2!$C1:$C70,MATCH($B8,Sheet2!$B1:$B70,0)),"")
I9: =IFERROR(INDEX(Sheet2!$C1:$C70,MATCH($B9,Sheet2!$B1:$B70,0)),"")
I10: =IFERROR(INDEX(Sheet2!$C1:$C70,MATCH($B10,Sheet2!$B1:$B70,0)),"")
I11: =IFERROR(INDEX(Sheet2!$C1:$C70,MATCH($B11,Sheet2!$B1:$B70,0)),"")
I12: =IFERROR(INDEX(Sheet2!$C1:$C70,MATCH($B12,Sheet2!$B1:$B70,0)),"")
I13: =IFERROR(INDEX(Sheet2!$C1:$C70,MATCH($B13,Sheet2!$B1:$B70,0)),"")
I14: =IFERROR(INDEX(Sheet2!$C1:$C70,MATCH($B14,Sheet2!$B1:$B70,0)),"")
I15: =IFERROR(INDEX(Sheet2!$C1:$C70,MATCH($B15,Sheet2!$B1:$B70,0)),"")
I16: =IFERROR(INDEX(Sheet2!$C1:$C70,MATCH($B16,Sheet2!$B1:$B70,0)),"")
I17: =IFERROR(INDEX(Sheet2!$C1:$C70,MATCH($B17,Sheet2!$B1:$B70,0)),"")
I18: =IFERROR(INDEX(Sheet2!$C1:$C70,MATCH($B18,Sheet2!$B1:$B70,0)),"")
I19: =IFERROR(INDEX(Sheet2!$C1:$C70,MATCH($B19,Sheet2!$B1:$B70,0)),"")
I20: =IFERROR(INDEX(Sheet2!$C1:$C70,MATCH($B20,Sheet2!$B1:$B70,0)),"")
I21: =IFERROR(INDEX(Sheet2!$C1:$C70,MATCH($B21,Sheet2!$B1:$B70,0)),"")
I22: =IFERROR(INDEX(Sheet2!$C1:$C70,MATCH($B22,Sheet2!$B1:$B70,0)),"")
I23: =IFERROR(INDEX(Sheet2!$C1:$C70,MATCH($B23,Sheet2!$B1:$B70,0)),"")
I24: =IFERROR(INDEX(Sheet2!$C1:$C70,MATCH($B24,Sheet2!$B1:$B70,0)),"")
I25: =IFERROR(INDEX(Sheet2!$C1:$C70,MATCH($B25,Sheet2!$B1:$B70,0)),"")
I26: =IFERROR(INDEX(Sheet2!$C1:$C70,MATCH($B26,Sheet2!$B1:$B70,0)),"")
I27: =IFERROR(INDEX(Sheet2!$C1:$C70,MATCH($B27,Sheet2!$B1:$B70,0)),"")
I28: =IFERROR(INDEX(Sheet2!$C1:$C70,MATCH($B28,Sheet2!$B1:$B70,0)),"")
I29: =IFERROR(INDEX(Sheet2!$C1:$C70,MATCH($B29,Sheet2!$B1:$B70,0)),"")
I30: =IFERROR(INDEX(Sheet2!$C1:$C70,MATCH($B30,Sheet2!$B1:$B70,0)),"")
I31: =IFERROR(INDEX(Sheet2!$C1:$C70,MATCH($B31,Sheet2!$B1:$B70,0)),"")
I32: =IFERROR(INDEX(Sheet2!$C1:$C70,MATCH($B32,Sheet2!$B1:$B70,0)),"")
I33: =IFERROR(INDEX(Sheet2!$C1:$C70,MATCH($B33,Sheet2!$B1:$B70,0)),"")
I34: =IFERROR(INDEX(Sheet2!$C1:$C70,MATCH($B34,Sheet2!$B1:$B70,0)),"")
I35: =IFERROR(INDEX(Sheet2!$C1:$C70,MATCH($B35,Sheet2!$B1:$B70,0)),"")
I36: =IFERROR(INDEX(Sheet2!$C1:$C70,MATCH($B36,Sheet2!$B1:$B70,0)),"")
I37: =IFERROR(INDEX(Sheet2!$C1:$C70,MATCH($B37,Sheet2!$B1:$B70,0)),"")
I38: =IFERROR(INDEX(Sheet2!$C1:$C70,MATCH($B38,Sheet2!$B1:$B70,0)),"")
I39: =IFERROR(INDEX(Sheet2!$C1:$C70,MATCH($B39,Sheet2!$B1:$B70,0)),"")
I40: =IFERROR(INDEX(Sheet2!$C1:$C70,MATCH($B40,Sheet2!$B1:$B70,0)),"")
...

Sheet Sheet3
A1: A Rack module
A2: B movement module
A3: C feeder module
A4: D tools module
A5: E Transport module
A6: F position module
A7: G auxiliary module

Sheet Sheet4
A1: associated elements failure mode
A2: elements failure mode
A3: Failure mode trigger by element(output)
A4: Failure mode trigger by senesor(input)

Sheet Sheet2
A1: {=IFERROR(INDEX($B$1:$B$70,SMALL(IFERROR(MATCH(IF(FIND(CELL("contents"),$B$1:$B$70)>0,$B$1:$B$70,""),$B$1:$B$70,0),""),ROW(B1))),"")} | B1: Air source | C1: Airs | D1: Abnormal air source pressure | E1: NEW
A2: {=IFERROR(INDEX($B$1:$B$70,SMALL(IFERROR(MATCH(IF(FIND(CELL("contents"),$B$1:$B$70)>0,$B$1:$B$70,""),$B$1:$B$70,0),""),ROW(B2))),"")} | B2: Ammeter | C2: AmM | D2: The ammeter is abnormal | E2: NEW
A3: {=IFERROR(INDEX($B$1:$B$70,SMALL(IFERROR(MATCH(IF(FIND(CELL("contents"),$B$1:$B$70)>0,$B$1:$B$70,""),$B$1:$B$70,0),""),ROW(B3))),"")} | B3: Barcode scanner | C3: Scan | D3: Reads QR code abnormally | E3: NEW
A4: {=IFERROR(INDEX($B$1:$B$70,SMALL(IFERROR(MATCH(IF(FIND(CELL("contents"),$B$1:$B$70)>0,$B$1:$B$70,""),$B$1:$B$70,0),""),ROW(B4))),"")} | B4: Burner | C4: Burner | D4: Abnormal communication of the programmer | E4: Abnormal programming | F4: NEW
A5: {=IFERROR(INDEX($B$1:$B$70,SMALL(IFERROR(MATCH(IF(FIND(CELL("contents"),$B$1:$B$70)>0,$B$1:$B$70,""),$B$1:$B$70,0),""),ROW(B5))),"")} | B5: CCD | C5: CCD | D5: Abnormal change of model program | E5: Abnormal data transmission | F5: Abnormal photography | G5: controller or communication error | H5: NEW
A6: {=IFERROR(INDEX($B$1:$B$70,SMALL(IFERROR(MATCH(IF(FIND(CELL("contents"),$B$1:$B$70)>0,$B$1:$B$70,""),$B$1:$B$70,0),""),ROW(B6))),"")} | B6: Communication (internal equipment) | C6: - | D6: communication error | E6: NEW
A7: {=IFERROR(INDEX($B$1:$B$70,SMALL(IFERROR(MATCH(IF(FIND(CELL("contents"),$B$1:$B$70)>0,$B$1:$B$70,""),$B$1:$B$70,0),""),ROW(B7))),"")} | B7: Constant temperature system | C7: Constant-temp | D7: Abnormal water level | E7: Constant temp water tank connect failed | F7: NEW
A8: {=IFERROR(INDEX($B$1:$B$70,SMALL(IFERROR(MATCH(IF(FIND(CELL("contents"),$B$1:$B$70)>0,$B$1:$B$70,""),$B$1:$B$70,0),""),ROW(B8))),"")} | B8: Counter | C8: Counter | D8: NEW
A9: {=IFERROR(INDEX($B$1:$B$70,SMALL(IFERROR(MATCH(IF(FIND(CELL("contents"),$B$1:$B$70)>0,$B$1:$B$70,""),$B$1:$B$70,0),""),ROW(B9))),"")} | B9: Cylinder | C9: Cy | D9: Cylinder reset abnormal | E9: Cylinder set abnormal | F9: NEW
A10: {=IFERROR(INDEX($B$1:$B$70,SMALL(IFERROR(MATCH(IF(FIND(CELL("contents"),$B$1:$B$70)>0,$B$1:$B$70,""),$B$1:$B$70,0),""),ROW(B10))),"")} | B10: DD motor | C10: Md | D10: Abnormal motor operation | E10: NEW
A11: {=IFERROR(INDEX($B$1:$B$70,SMALL(IFERROR(MATCH(IF(FIND(CELL("contents"),$B$1:$B$70)>0,$B$1:$B$70,""),$B$1:$B$70,0),""),ROW(B11))),"")} | B11: Dot/Spray glue system | C11: Spray-glue | D11: Abnormal spray adhesive flow detection | E11: IO signal abnormal | F11: NEW
A12: {=IFERROR(INDEX($B$1:$B$70,SMALL(IFERROR(MATCH(IF(FIND(CELL("contents"),$B$1:$B$70)>0,$B$1:$B$70,""),$B$1:$B$70,0),""),ROW(B12))),"")} | B12: Dynamic balancing | C12: Dynamic-balancing | D12: Abnormal dynamic balance test | E12: NEW
A13: {=IFERROR(INDEX($B$1:$B$70,SMALL(IFERROR(MATCH(IF(FIND(CELL("contents"),$B$1:$B$70)>0,$B$1:$B$70,""),$B$1:$B$70,0),""),ROW(B13))),"")} | B13: Electric cylinder | C13: Electric-cylinder | D13: Electric cylinder driver alarm | E13: Electric cylinder positive and negative limit alarm | F13: NEW
A14: {=IFERROR(INDEX($B$1:$B$70,SMALL(IFERROR(MATCH(IF(FIND(CELL("contents"),$B$1:$B$70)>0,$B$1:$B$70,""),$B$1:$B$70,0),""),ROW(B14))),"")} | B14: Electric gripper | C14: Electric-gripper | D14: Abnormal communication | E14: Abnormal parameter | F14: NEW
A15: {=IFERROR(INDEX($B$1:$B$70,SMALL(IFERROR(MATCH(IF(FIND(CELL("contents"),$B$1:$B$70)>0,$B$1:$B$70,""),$B$1:$B$70,0),""),ROW(B15))),"")} | B15: Electric spindle | C15: ESp | D15: The I/O signal is abnormal | E15: NEW
A16: {=IFERROR(INDEX($B$1:$B$70,SMALL(IFERROR(MATCH(IF(FIND(CELL("contents"),$B$1:$B$70)>0,$B$1:$B$70,""),$B$1:$B$70,0),""),ROW(B16))),"")} | B16: Electrostatic eliminator | C16: SE | D16: Static eliminator signal abnormality | E16: NEW
A17: {=IFERROR(INDEX($B$1:$B$70,SMALL(IFERROR(MATCH(IF(FIND(CELL("contents"),$B$1:$B$70)>0,$B$1:$B$70,""),$B$1:$B$70,0),""),ROW(B17))),"")} | B17: EMG stop button | C17: EMS | D17: Abnormal singal of safety door | E17: NEW
A18: {=IFERROR(INDEX($B$1:$B$70,SMALL(IFERROR(MATCH(IF(FIND(CELL("contents"),$B$1:$B$70)>0,$B$1:$B$70,""),$B$1:$B$70,0),""),ROW(B18))),"")} | B18: Glue dispensing system | C18: Glue-dispensing | D18: Signal Error | E18: NEW
A19: {=IFERROR(INDEX($B$1:$B$70,SMALL(IFERROR(MATCH(IF(FIND(CELL("contents"),$B$1:$B$70)>0,$B$1:$B$70,""),$B$1:$B$70,0),""),ROW(B19))),"")} | B19: Glue supply system | C19: Glue-supply | D19: Abnormal glue supply | E19: NEW
A20: {=IFERROR(INDEX($B$1:$B$70,SMALL(IFERROR(MATCH(IF(FIND(CELL("contents"),$B$1:$B$70)>0,$B$1:$B$70,""),$B$1:$B$70,0),""),ROW(B20))),"")} | B20: High-frequency equipment | C20: High-frequency | D20: Abnormal high-frequency heating | E20: High frequency heater abnormal alarm | F20: The I/O signal of the high-frequency device is abnormal | G20: NEW
A21: {=IFERROR(INDEX($B$1:$B$70,SMALL(IFERROR(MATCH(IF(FIND(CELL("contents"),$B$1:$B$70)>0,$B$1:$B$70,""),$B$1:$B$70,0),""),ROW(B21))),"")} | B21: Horizontal articulated robot | C21: SCARA | D21: Abnormal movement of the robot | E21: Robot alarm signal abnormal | F21: Robot IO signal abnormality | G21: NEW
A22: {=IFERROR(INDEX($B$1:$B$70,SMALL(IFERROR(MATCH(IF(FIND(CELL("contents"),$B$1:$B$70)>0,$B$1:$B$70,""),$B$1:$B$70,0),""),ROW(B22))),"")} | B22: Induction motor | C22: Mi | D22: Abnormal motor operation | E22: NEW
A23: {=IFERROR(INDEX($B$1:$B$70,SMALL(IFERROR(MATCH(IF(FIND(CELL("contents"),$B$1:$B$70)>0,$B$1:$B$70,""),$B$1:$B$70,0),""),ROW(B23))),"")} | B23: label feeder | C23: Label-feeder | D23: The last label is abnormal, please clear the label on the printing platform | E23: NEW
A24: {=IFERROR(INDEX($B$1:$B$70,SMALL(IFERROR(MATCH(IF(FIND(CELL("contents"),$B$1:$B$70)>0,$B$1:$B$70,""),$B$1:$B$70,0),""),ROW(B24))),"")} | B24: Laser | C24: Laser | D24: Laser engraving machine signal abnormality | E24: NEW
A25: {=IFERROR(INDEX($B$1:$B$70,SMALL(IFERROR(MATCH(IF(FIND(CELL("contents"),$B$1:$B$70)>0,$B$1:$B$70,""),$B$1:$B$70,0),""),ROW(B25))),"")} | B25: Life control | C25: - | D25: Service life reaches | E25: NEW
A26: {=IFERROR(INDEX($B$1:$B$70,SMALL(IFERROR(MATCH(IF(FIND(CELL("contents"),$B$1:$B$70)>0,$B$1:$B$70,""),$B$1:$B$70,0),""),ROW(B26))),"")} | B26: Light | C26: EL | D26: Abnormal light source | E26: NEW
A27: {=IFERROR(INDEX($B$1:$B$70,SMALL(IFERROR(MATCH(IF(FIND(CELL("contents"),$B$1:$B$70)>0,$B$1:$B$70,""),$B$1:$B$70,0),""),ROW(B27))),"")} | B27: Linear motor | C27: Ml | D27: NEW
A28: {=IFERROR(INDEX($B$1:$B$70,SMALL(IFERROR(MATCH(IF(FIND(CELL("contents"),$B$1:$B$70)>0,$B$1:$B$70,""),$B$1:$B$70,0),""),ROW(B28))),"")} | B28: Locking system | C28: Locking | D28: Abnormal change of model program | E28: Lock failure | F28: Locking system alarm | G28: locking timeout | H28: NEW
A29: {=IFERROR(INDEX($B$1:$B$70,SMALL(IFERROR(MATCH(IF(FIND(CELL("contents"),$B$1:$B$70)>0,$B$1:$B$70,""),$B$1:$B$70,0),""),ROW(B29))),"")} | B29: M2M | C29: - | D29: Handshake signal abnormal | E29: NEW
A30: {=IFERROR(INDEX($B$1:$B$70,SMALL(IFERROR(MATCH(IF(FIND(CELL("contents"),$B$1:$B$70)>0,$B$1:$B$70,""),$B$1:$B$70,0),""),ROW(B30))),"")} | B30: M2S | C30: - | D30: line change is abnormal | E30: MES connection is abnormal | F30: MES layer control data abnormality | G30: MES lock line | H30: NEW
A31: {=IFERROR(INDEX($B$1:$B$70,SMALL(IFERROR(MATCH(IF(FIND(CELL("contents"),$B$1:$B$70)>0,$B$1:$B$70,""),$B$1:$B$70,0),""),ROW(B31))),"")} | B31: Magnetizer | C31: Magnetizer | D31: System parameter setting error | E31: NEW
A32: {=IFERROR(INDEX($B$1:$B$70,SMALL(IFERROR(MATCH(IF(FIND(CELL("contents"),$B$1:$B$70)>0,$B$1:$B$70,""),$B$1:$B$70,0),""),ROW(B32))),"")} | B32: Others | C32: - | D32: KBK drove away from the safe parking position | E32: The fixture on the left lift platform is jammed | F32: The fixture on the right lift platform is jammed | G32: Unaccredited personnel | H32: NEW
A33: {=IFERROR(INDEX($B$1:$B$70,SMALL(IFERROR(MATCH(IF(FIND(CELL("contents"),$B$1:$B$70)>0,$B$1:$B$70,""),$B$1:$B$70,0),""),ROW(B33))),"")} | B33: Plug-in feeder | C33: Plug-in-feeder | D33: Abnormal feeding | E33: Feeder alarm | F33: IO signal abnormal | G33: NEW
A34: {=IFERROR(INDEX($B$1:$B$70,SMALL(IFERROR(MATCH(IF(FIND(CELL("contents"),$B$1:$B$70)>0,$B$1:$B$70,""),$B$1:$B$70,0),""),ROW(B34))),"")} | B34: Poor material | C34: - | D34: Poor material quality | E34: NEW
A35: {=IFERROR(INDEX($B$1:$B$70,SMALL(IFERROR(MATCH(IF(FIND(CELL("contents"),$B$1:$B$70)>0,$B$1:$B$70,""),$B$1:$B$70,0),""),ROW(B35))),"")} | B35: Poor production quality | C35: - | D35: Poor equipment quality | E35: Poor product quality | F35: Quality abnormal | G35: NEW
A36: {=IFERROR(INDEX($B$1:$B$70,SMALL(IFERROR(MATCH(IF(FIND(CELL("contents"),$B$1:$B$70)>0,$B$1:$B$70,""),$B$1:$B$70,0),""),ROW(B36))),"")} | B36: Power meter | C36: PowM | D36: The power meter shows abnormal | E36: NEW
A37: {=IFERROR(INDEX($B$1:$B$70,SMALL(IFERROR(MATCH(IF(FIND(CELL("contents"),$B$1:$B$70)>0,$B$1:$B$70,""),$B$1:$B$70,0),""),ROW(B37))),"")} | B37: Power roller | C37: PRol | D37: Transmission anomaly | E37: NEW
A38: {=IFERROR(INDEX($B$1:$B$70,SMALL(IFERROR(MATCH(IF(FIND(CELL("contents"),$B$1:$B$70)>0,$B$1:$B$70,""),$B$1:$B$70,0),""),ROW(B38))),"")} | B38: Pressure gauge | C38: PreG | D38: abnormal pressure | E38: NEW
A39: {=IFERROR(INDEX($B$1:$B$70,SMALL(IFERROR(MATCH(IF(FIND(CELL("contents"),$B$1:$B$70)>0,$B$1:$B$70,""),$B$1:$B$70,0),""),ROW(B39))),"")} | B39: Printer | C39: Printer | D39: Barcode printing abnormal | E39: NEW
A40: {=IFERROR(INDEX($B$1:$B$70,SMALL(IFERROR(MATCH(IF(FIND(CELL("contents"),$B$1:$B$70)>0,$B$1:$B$70,""),$B$1:$B$70,0),""),ROW(B40))),"")} | B40: Process | C40: - | D40: failed to RW | E40: Module inital abnormal | F40: parameter unabled | G40: Parameter upper limit reached | H40: Program static parameter exception | I40: Sequence work fail | J40: The capacity of the hard disk has reached the limit, and further detection is not allowed!Please clean up the hard disk data to free up space | K40: The data conversion failed | L40: The motion parameter list is incorrect | M40: Waiting to do something. | N40: NEW
...
